{
 "cells": [
  {
   "cell_type": "markdown",
   "id": "19bb081f",
   "metadata": {},
   "source": [
    "1> Set the variable test1 to the string 'This is a test of the emergency text system,' and save test1 to a file named test.txt."
   ]
  },
  {
   "cell_type": "code",
   "execution_count": 1,
   "id": "5b771595",
   "metadata": {},
   "outputs": [],
   "source": [
    "test1= \"This is a test of the emergency text system\""
   ]
  },
  {
   "cell_type": "code",
   "execution_count": 2,
   "id": "4a038762",
   "metadata": {},
   "outputs": [
    {
     "name": "stdout",
     "output_type": "stream",
     "text": [
      "Done\n"
     ]
    }
   ],
   "source": [
    "with open(\"test.txt\",\"w\") as f:\n",
    "    f.write(test1)\n",
    "    print(\"Done\")"
   ]
  },
  {
   "cell_type": "code",
   "execution_count": 3,
   "id": "cb7c6271",
   "metadata": {},
   "outputs": [],
   "source": [
    "f.close()"
   ]
  },
  {
   "cell_type": "markdown",
   "id": "f20e69fc",
   "metadata": {},
   "source": [
    "2> Read the contents of the file test.txt into the variable test2. Is there a difference between test 1 and test 2?"
   ]
  },
  {
   "cell_type": "code",
   "execution_count": 4,
   "id": "2784c126",
   "metadata": {},
   "outputs": [
    {
     "name": "stdout",
     "output_type": "stream",
     "text": [
      "Done\n"
     ]
    }
   ],
   "source": [
    "with open(\"test.txt\",\"r\") as f:\n",
    "    test2=f.read()\n",
    "    print(\"Done\")"
   ]
  },
  {
   "cell_type": "code",
   "execution_count": 5,
   "id": "981accf5",
   "metadata": {},
   "outputs": [
    {
     "data": {
      "text/plain": [
       "True"
      ]
     },
     "execution_count": 5,
     "metadata": {},
     "output_type": "execute_result"
    }
   ],
   "source": [
    "test1==test2"
   ]
  },
  {
   "cell_type": "markdown",
   "id": "d7d8df2b",
   "metadata": {},
   "source": [
    "3> Create a CSV file called books.csv by using these lines:\n",
    "\n",
    "title,author,year\n",
    "\n",
    "The Weirdstone of Brisingamen,Alan Garner,1960\n",
    "\n",
    "Perdido Street Station,China Miéville,2000\n",
    "\n",
    "Thud!,Terry Pratchett,2005\n",
    "\n",
    "The Spellman Files,Lisa Lutz,2007\n",
    "\n",
    "Small Gods,Terry Pratchett,1992"
   ]
  },
  {
   "cell_type": "code",
   "execution_count": 6,
   "id": "3f77110d",
   "metadata": {},
   "outputs": [
    {
     "name": "stdout",
     "output_type": "stream",
     "text": [
      "Done\n"
     ]
    }
   ],
   "source": [
    "text=\"\"\"\n",
    "\n",
    "title,author,year\n",
    "\n",
    "The Weirdstone of Brisingamen,Alan Garner,1960\n",
    "\n",
    "Perdido Street Station,China Miéville,2000\n",
    "\n",
    "Thud!,Terry Pratchett,2005\n",
    "\n",
    "The Spellman Files,Lisa Lutz,2007\n",
    "\n",
    "Small Gods,Terry Pratchett,1992\"\"\"\n",
    "with open(\"books.csv\",\"w\") as a:\n",
    "    a.write(text)\n",
    "    print(\"Done\")"
   ]
  },
  {
   "cell_type": "markdown",
   "id": "cb678ec8",
   "metadata": {},
   "source": [
    "4> Use the sqlite3 module to create a SQLite database called books.db, and a table called books with these fields: title (text), author (text), and year (integer)."
   ]
  },
  {
   "cell_type": "code",
   "execution_count": 14,
   "id": "c63727cc",
   "metadata": {},
   "outputs": [
    {
     "name": "stdout",
     "output_type": "stream",
     "text": [
      "Defaulting to user installation because normal site-packages is not writeable\n",
      "Note: you may need to restart the kernel to use updated packages.\n"
     ]
    },
    {
     "name": "stderr",
     "output_type": "stream",
     "text": [
      "ERROR: Could not find a version that satisfies the requirement sqlite3 (from versions: none)\n",
      "ERROR: No matching distribution found for sqlite3\n"
     ]
    }
   ],
   "source": [
    "pip install sqlite3 "
   ]
  },
  {
   "cell_type": "code",
   "execution_count": 16,
   "id": "dce7911c",
   "metadata": {},
   "outputs": [],
   "source": [
    "import sqlite3\n",
    "db = sqlite3.connect(\"books.db\")\n",
    "curs = db.cursor()"
   ]
  },
  {
   "cell_type": "code",
   "execution_count": 18,
   "id": "1d39d910",
   "metadata": {},
   "outputs": [
    {
     "ename": "OperationalError",
     "evalue": "table books already exists",
     "output_type": "error",
     "traceback": [
      "\u001b[1;31m---------------------------------------------------------------------------\u001b[0m",
      "\u001b[1;31mOperationalError\u001b[0m                          Traceback (most recent call last)",
      "Cell \u001b[1;32mIn[18], line 1\u001b[0m\n\u001b[1;32m----> 1\u001b[0m curs\u001b[38;5;241m.\u001b[39mexecute(\u001b[38;5;124m\"\u001b[39m\u001b[38;5;124mcreate table books (title TEXT,author TEXT,year INTEGER)\u001b[39m\u001b[38;5;124m\"\u001b[39m)\n",
      "\u001b[1;31mOperationalError\u001b[0m: table books already exists"
     ]
    }
   ],
   "source": [
    "curs.execute(\"create table books (title TEXT,author TEXT,year INTEGER)\")"
   ]
  },
  {
   "cell_type": "code",
   "execution_count": 19,
   "id": "f0f22f1a",
   "metadata": {},
   "outputs": [],
   "source": [
    "db.commit()"
   ]
  },
  {
   "cell_type": "markdown",
   "id": "50218343",
   "metadata": {},
   "source": [
    "5> Read books.csv and insert its data into the book table."
   ]
  },
  {
   "cell_type": "code",
   "execution_count": 20,
   "id": "e50be177",
   "metadata": {},
   "outputs": [
    {
     "name": "stdout",
     "output_type": "stream",
     "text": [
      "{None: ['title,author,year']}\n"
     ]
    }
   ],
   "source": [
    "import csv\n",
    "import sqlite3\n",
    "ins_str = 'insert into book (title, author, year) values(?, ?, ?)'\n",
    "with open('books.csv', 'rt') as f:\n",
    "    books = csv.DictReader(f, delimiter=';')\n",
    "    header = next(books)\n",
    "    print(header)\n"
   ]
  },
  {
   "cell_type": "markdown",
   "id": "ef05cba4",
   "metadata": {},
   "source": [
    "6> Select and print the title column from the book table in alphabetical order."
   ]
  },
  {
   "cell_type": "code",
   "execution_count": 22,
   "id": "4274bba8",
   "metadata": {},
   "outputs": [],
   "source": [
    "sql = 'select title from books order by title asc'\n",
    "for row in db.execute(sql):\n",
    "    print(row)"
   ]
  },
  {
   "cell_type": "code",
   "execution_count": 23,
   "id": "77893cce",
   "metadata": {},
   "outputs": [],
   "source": [
    "#to print the title value without that tuple stuff (parentheses and comma):\n",
    "for row in db.execute(sql):\n",
    "    print(row[0])"
   ]
  },
  {
   "cell_type": "markdown",
   "id": "d18215eb",
   "metadata": {},
   "source": [
    "7> From the book table, select and print all columns in the order of publication."
   ]
  },
  {
   "cell_type": "code",
   "execution_count": 26,
   "id": "28cfb849",
   "metadata": {},
   "outputs": [],
   "source": [
    "for row in db.execute('select * from books order by year'):\n",
    "    print(row)"
   ]
  },
  {
   "cell_type": "code",
   "execution_count": 27,
   "id": "3eb119f1",
   "metadata": {},
   "outputs": [],
   "source": [
    "for row in db.execute('select * from books order by year'):\n",
    "    print(*row, sep=', ')"
   ]
  },
  {
   "cell_type": "markdown",
   "id": "8034a3c1",
   "metadata": {},
   "source": [
    "8> Use the sqlalchemy module to connect to the sqlite3 database books.db that you just made in exercise 6."
   ]
  },
  {
   "cell_type": "code",
   "execution_count": 3,
   "id": "67adfce8",
   "metadata": {},
   "outputs": [],
   "source": [
    "import sqlalchemy\n",
    "conn = sqlalchemy.create_engine('sqlite:///books.db')\n",
    "sql = 'select title from books order by title asc'\n",
    "rows = conn.execute(sql)\n",
    "for row in rows:\n",
    "    print(row)"
   ]
  },
  {
   "cell_type": "markdown",
   "id": "708769d7",
   "metadata": {},
   "source": [
    "9> Install the Redis server and the Python redis library (pip install redis) on your computer. Create a Redis hash called test with the fields count (1) and name ('Fester Bestertester'). Print all the fields for test."
   ]
  },
  {
   "cell_type": "code",
   "execution_count": 4,
   "id": "6bf89cce",
   "metadata": {},
   "outputs": [
    {
     "name": "stdout",
     "output_type": "stream",
     "text": [
      "Defaulting to user installation because normal site-packages is not writeable\n",
      "Requirement already satisfied: redis in c:\\users\\shree\\appdata\\roaming\\python\\python311\\site-packages (5.0.1)\n",
      "Note: you may need to restart the kernel to use updated packages.\n"
     ]
    }
   ],
   "source": [
    "pip install redis"
   ]
  },
  {
   "cell_type": "code",
   "execution_count": 5,
   "id": "be64d1a7",
   "metadata": {},
   "outputs": [
    {
     "ename": "ConnectionError",
     "evalue": "Error 10061 connecting to localhost:6379. No connection could be made because the target machine actively refused it.",
     "output_type": "error",
     "traceback": [
      "\u001b[1;31m---------------------------------------------------------------------------\u001b[0m",
      "\u001b[1;31mConnectionRefusedError\u001b[0m                    Traceback (most recent call last)",
      "File \u001b[1;32m~\\AppData\\Roaming\\Python\\Python311\\site-packages\\redis\\connection.py:264\u001b[0m, in \u001b[0;36mAbstractConnection.connect\u001b[1;34m(self)\u001b[0m\n\u001b[0;32m    263\u001b[0m \u001b[38;5;28;01mtry\u001b[39;00m:\n\u001b[1;32m--> 264\u001b[0m     sock \u001b[38;5;241m=\u001b[39m \u001b[38;5;28mself\u001b[39m\u001b[38;5;241m.\u001b[39mretry\u001b[38;5;241m.\u001b[39mcall_with_retry(\n\u001b[0;32m    265\u001b[0m         \u001b[38;5;28;01mlambda\u001b[39;00m: \u001b[38;5;28mself\u001b[39m\u001b[38;5;241m.\u001b[39m_connect(), \u001b[38;5;28;01mlambda\u001b[39;00m error: \u001b[38;5;28mself\u001b[39m\u001b[38;5;241m.\u001b[39mdisconnect(error)\n\u001b[0;32m    266\u001b[0m     )\n\u001b[0;32m    267\u001b[0m \u001b[38;5;28;01mexcept\u001b[39;00m socket\u001b[38;5;241m.\u001b[39mtimeout:\n",
      "File \u001b[1;32m~\\AppData\\Roaming\\Python\\Python311\\site-packages\\redis\\retry.py:46\u001b[0m, in \u001b[0;36mRetry.call_with_retry\u001b[1;34m(self, do, fail)\u001b[0m\n\u001b[0;32m     45\u001b[0m \u001b[38;5;28;01mtry\u001b[39;00m:\n\u001b[1;32m---> 46\u001b[0m     \u001b[38;5;28;01mreturn\u001b[39;00m do()\n\u001b[0;32m     47\u001b[0m \u001b[38;5;28;01mexcept\u001b[39;00m \u001b[38;5;28mself\u001b[39m\u001b[38;5;241m.\u001b[39m_supported_errors \u001b[38;5;28;01mas\u001b[39;00m error:\n",
      "File \u001b[1;32m~\\AppData\\Roaming\\Python\\Python311\\site-packages\\redis\\connection.py:265\u001b[0m, in \u001b[0;36mAbstractConnection.connect.<locals>.<lambda>\u001b[1;34m()\u001b[0m\n\u001b[0;32m    263\u001b[0m \u001b[38;5;28;01mtry\u001b[39;00m:\n\u001b[0;32m    264\u001b[0m     sock \u001b[38;5;241m=\u001b[39m \u001b[38;5;28mself\u001b[39m\u001b[38;5;241m.\u001b[39mretry\u001b[38;5;241m.\u001b[39mcall_with_retry(\n\u001b[1;32m--> 265\u001b[0m         \u001b[38;5;28;01mlambda\u001b[39;00m: \u001b[38;5;28mself\u001b[39m\u001b[38;5;241m.\u001b[39m_connect(), \u001b[38;5;28;01mlambda\u001b[39;00m error: \u001b[38;5;28mself\u001b[39m\u001b[38;5;241m.\u001b[39mdisconnect(error)\n\u001b[0;32m    266\u001b[0m     )\n\u001b[0;32m    267\u001b[0m \u001b[38;5;28;01mexcept\u001b[39;00m socket\u001b[38;5;241m.\u001b[39mtimeout:\n",
      "File \u001b[1;32m~\\AppData\\Roaming\\Python\\Python311\\site-packages\\redis\\connection.py:627\u001b[0m, in \u001b[0;36mConnection._connect\u001b[1;34m(self)\u001b[0m\n\u001b[0;32m    626\u001b[0m \u001b[38;5;28;01mif\u001b[39;00m err \u001b[38;5;129;01mis\u001b[39;00m \u001b[38;5;129;01mnot\u001b[39;00m \u001b[38;5;28;01mNone\u001b[39;00m:\n\u001b[1;32m--> 627\u001b[0m     \u001b[38;5;28;01mraise\u001b[39;00m err\n\u001b[0;32m    628\u001b[0m \u001b[38;5;28;01mraise\u001b[39;00m \u001b[38;5;167;01mOSError\u001b[39;00m(\u001b[38;5;124m\"\u001b[39m\u001b[38;5;124msocket.getaddrinfo returned an empty list\u001b[39m\u001b[38;5;124m\"\u001b[39m)\n",
      "File \u001b[1;32m~\\AppData\\Roaming\\Python\\Python311\\site-packages\\redis\\connection.py:615\u001b[0m, in \u001b[0;36mConnection._connect\u001b[1;34m(self)\u001b[0m\n\u001b[0;32m    614\u001b[0m \u001b[38;5;66;03m# connect\u001b[39;00m\n\u001b[1;32m--> 615\u001b[0m sock\u001b[38;5;241m.\u001b[39mconnect(socket_address)\n\u001b[0;32m    617\u001b[0m \u001b[38;5;66;03m# set the socket_timeout now that we're connected\u001b[39;00m\n",
      "\u001b[1;31mConnectionRefusedError\u001b[0m: [WinError 10061] No connection could be made because the target machine actively refused it",
      "\nDuring handling of the above exception, another exception occurred:\n",
      "\u001b[1;31mConnectionError\u001b[0m                           Traceback (most recent call last)",
      "Cell \u001b[1;32mIn[5], line 3\u001b[0m\n\u001b[0;32m      1\u001b[0m \u001b[38;5;28;01mimport\u001b[39;00m \u001b[38;5;21;01mredis\u001b[39;00m\n\u001b[0;32m      2\u001b[0m conn \u001b[38;5;241m=\u001b[39m redis\u001b[38;5;241m.\u001b[39mRedis()\n\u001b[1;32m----> 3\u001b[0m conn\u001b[38;5;241m.\u001b[39mdelete(\u001b[38;5;124m'\u001b[39m\u001b[38;5;124mtest\u001b[39m\u001b[38;5;124m'\u001b[39m)\n",
      "File \u001b[1;32m~\\AppData\\Roaming\\Python\\Python311\\site-packages\\redis\\commands\\core.py:1712\u001b[0m, in \u001b[0;36mBasicKeyCommands.delete\u001b[1;34m(self, *names)\u001b[0m\n\u001b[0;32m   1708\u001b[0m \u001b[38;5;28;01mdef\u001b[39;00m \u001b[38;5;21mdelete\u001b[39m(\u001b[38;5;28mself\u001b[39m, \u001b[38;5;241m*\u001b[39mnames: KeyT) \u001b[38;5;241m-\u001b[39m\u001b[38;5;241m>\u001b[39m ResponseT:\n\u001b[0;32m   1709\u001b[0m \u001b[38;5;250m    \u001b[39m\u001b[38;5;124;03m\"\"\"\u001b[39;00m\n\u001b[0;32m   1710\u001b[0m \u001b[38;5;124;03m    Delete one or more keys specified by ``names``\u001b[39;00m\n\u001b[0;32m   1711\u001b[0m \u001b[38;5;124;03m    \"\"\"\u001b[39;00m\n\u001b[1;32m-> 1712\u001b[0m     \u001b[38;5;28;01mreturn\u001b[39;00m \u001b[38;5;28mself\u001b[39m\u001b[38;5;241m.\u001b[39mexecute_command(\u001b[38;5;124m\"\u001b[39m\u001b[38;5;124mDEL\u001b[39m\u001b[38;5;124m\"\u001b[39m, \u001b[38;5;241m*\u001b[39mnames)\n",
      "File \u001b[1;32m~\\AppData\\Roaming\\Python\\Python311\\site-packages\\redis\\client.py:533\u001b[0m, in \u001b[0;36mRedis.execute_command\u001b[1;34m(self, *args, **options)\u001b[0m\n\u001b[0;32m    531\u001b[0m pool \u001b[38;5;241m=\u001b[39m \u001b[38;5;28mself\u001b[39m\u001b[38;5;241m.\u001b[39mconnection_pool\n\u001b[0;32m    532\u001b[0m command_name \u001b[38;5;241m=\u001b[39m args[\u001b[38;5;241m0\u001b[39m]\n\u001b[1;32m--> 533\u001b[0m conn \u001b[38;5;241m=\u001b[39m \u001b[38;5;28mself\u001b[39m\u001b[38;5;241m.\u001b[39mconnection \u001b[38;5;129;01mor\u001b[39;00m pool\u001b[38;5;241m.\u001b[39mget_connection(command_name, \u001b[38;5;241m*\u001b[39m\u001b[38;5;241m*\u001b[39moptions)\n\u001b[0;32m    535\u001b[0m \u001b[38;5;28;01mtry\u001b[39;00m:\n\u001b[0;32m    536\u001b[0m     \u001b[38;5;28;01mreturn\u001b[39;00m conn\u001b[38;5;241m.\u001b[39mretry\u001b[38;5;241m.\u001b[39mcall_with_retry(\n\u001b[0;32m    537\u001b[0m         \u001b[38;5;28;01mlambda\u001b[39;00m: \u001b[38;5;28mself\u001b[39m\u001b[38;5;241m.\u001b[39m_send_command_parse_response(\n\u001b[0;32m    538\u001b[0m             conn, command_name, \u001b[38;5;241m*\u001b[39margs, \u001b[38;5;241m*\u001b[39m\u001b[38;5;241m*\u001b[39moptions\n\u001b[0;32m    539\u001b[0m         ),\n\u001b[0;32m    540\u001b[0m         \u001b[38;5;28;01mlambda\u001b[39;00m error: \u001b[38;5;28mself\u001b[39m\u001b[38;5;241m.\u001b[39m_disconnect_raise(conn, error),\n\u001b[0;32m    541\u001b[0m     )\n",
      "File \u001b[1;32m~\\AppData\\Roaming\\Python\\Python311\\site-packages\\redis\\connection.py:1086\u001b[0m, in \u001b[0;36mConnectionPool.get_connection\u001b[1;34m(self, command_name, *keys, **options)\u001b[0m\n\u001b[0;32m   1082\u001b[0m     \u001b[38;5;28mself\u001b[39m\u001b[38;5;241m.\u001b[39m_in_use_connections\u001b[38;5;241m.\u001b[39madd(connection)\n\u001b[0;32m   1084\u001b[0m \u001b[38;5;28;01mtry\u001b[39;00m:\n\u001b[0;32m   1085\u001b[0m     \u001b[38;5;66;03m# ensure this connection is connected to Redis\u001b[39;00m\n\u001b[1;32m-> 1086\u001b[0m     connection\u001b[38;5;241m.\u001b[39mconnect()\n\u001b[0;32m   1087\u001b[0m     \u001b[38;5;66;03m# connections that the pool provides should be ready to send\u001b[39;00m\n\u001b[0;32m   1088\u001b[0m     \u001b[38;5;66;03m# a command. if not, the connection was either returned to the\u001b[39;00m\n\u001b[0;32m   1089\u001b[0m     \u001b[38;5;66;03m# pool before all data has been read or the socket has been\u001b[39;00m\n\u001b[0;32m   1090\u001b[0m     \u001b[38;5;66;03m# closed. either way, reconnect and verify everything is good.\u001b[39;00m\n\u001b[0;32m   1091\u001b[0m     \u001b[38;5;28;01mtry\u001b[39;00m:\n",
      "File \u001b[1;32m~\\AppData\\Roaming\\Python\\Python311\\site-packages\\redis\\connection.py:270\u001b[0m, in \u001b[0;36mAbstractConnection.connect\u001b[1;34m(self)\u001b[0m\n\u001b[0;32m    268\u001b[0m     \u001b[38;5;28;01mraise\u001b[39;00m \u001b[38;5;167;01mTimeoutError\u001b[39;00m(\u001b[38;5;124m\"\u001b[39m\u001b[38;5;124mTimeout connecting to server\u001b[39m\u001b[38;5;124m\"\u001b[39m)\n\u001b[0;32m    269\u001b[0m \u001b[38;5;28;01mexcept\u001b[39;00m \u001b[38;5;167;01mOSError\u001b[39;00m \u001b[38;5;28;01mas\u001b[39;00m e:\n\u001b[1;32m--> 270\u001b[0m     \u001b[38;5;28;01mraise\u001b[39;00m \u001b[38;5;167;01mConnectionError\u001b[39;00m(\u001b[38;5;28mself\u001b[39m\u001b[38;5;241m.\u001b[39m_error_message(e))\n\u001b[0;32m    272\u001b[0m \u001b[38;5;28mself\u001b[39m\u001b[38;5;241m.\u001b[39m_sock \u001b[38;5;241m=\u001b[39m sock\n\u001b[0;32m    273\u001b[0m \u001b[38;5;28;01mtry\u001b[39;00m:\n",
      "\u001b[1;31mConnectionError\u001b[0m: Error 10061 connecting to localhost:6379. No connection could be made because the target machine actively refused it."
     ]
    }
   ],
   "source": [
    "import redis\n",
    "conn = redis.Redis()\n",
    "conn.delete('test')"
   ]
  },
  {
   "cell_type": "code",
   "execution_count": 6,
   "id": "44a97308",
   "metadata": {},
   "outputs": [
    {
     "name": "stderr",
     "output_type": "stream",
     "text": [
      "C:\\Users\\SHREE\\AppData\\Local\\Temp\\ipykernel_12072\\2098504947.py:1: DeprecationWarning: Redis.hmset() is deprecated. Use Redis.hset() instead.\n",
      "  conn.hmset('test', {'count': 1, 'name': 'Fester Bestertester'})\n"
     ]
    },
    {
     "ename": "ConnectionError",
     "evalue": "Error 10061 connecting to localhost:6379. No connection could be made because the target machine actively refused it.",
     "output_type": "error",
     "traceback": [
      "\u001b[1;31m---------------------------------------------------------------------------\u001b[0m",
      "\u001b[1;31mConnectionRefusedError\u001b[0m                    Traceback (most recent call last)",
      "File \u001b[1;32m~\\AppData\\Roaming\\Python\\Python311\\site-packages\\redis\\connection.py:264\u001b[0m, in \u001b[0;36mAbstractConnection.connect\u001b[1;34m(self)\u001b[0m\n\u001b[0;32m    263\u001b[0m \u001b[38;5;28;01mtry\u001b[39;00m:\n\u001b[1;32m--> 264\u001b[0m     sock \u001b[38;5;241m=\u001b[39m \u001b[38;5;28mself\u001b[39m\u001b[38;5;241m.\u001b[39mretry\u001b[38;5;241m.\u001b[39mcall_with_retry(\n\u001b[0;32m    265\u001b[0m         \u001b[38;5;28;01mlambda\u001b[39;00m: \u001b[38;5;28mself\u001b[39m\u001b[38;5;241m.\u001b[39m_connect(), \u001b[38;5;28;01mlambda\u001b[39;00m error: \u001b[38;5;28mself\u001b[39m\u001b[38;5;241m.\u001b[39mdisconnect(error)\n\u001b[0;32m    266\u001b[0m     )\n\u001b[0;32m    267\u001b[0m \u001b[38;5;28;01mexcept\u001b[39;00m socket\u001b[38;5;241m.\u001b[39mtimeout:\n",
      "File \u001b[1;32m~\\AppData\\Roaming\\Python\\Python311\\site-packages\\redis\\retry.py:46\u001b[0m, in \u001b[0;36mRetry.call_with_retry\u001b[1;34m(self, do, fail)\u001b[0m\n\u001b[0;32m     45\u001b[0m \u001b[38;5;28;01mtry\u001b[39;00m:\n\u001b[1;32m---> 46\u001b[0m     \u001b[38;5;28;01mreturn\u001b[39;00m do()\n\u001b[0;32m     47\u001b[0m \u001b[38;5;28;01mexcept\u001b[39;00m \u001b[38;5;28mself\u001b[39m\u001b[38;5;241m.\u001b[39m_supported_errors \u001b[38;5;28;01mas\u001b[39;00m error:\n",
      "File \u001b[1;32m~\\AppData\\Roaming\\Python\\Python311\\site-packages\\redis\\connection.py:265\u001b[0m, in \u001b[0;36mAbstractConnection.connect.<locals>.<lambda>\u001b[1;34m()\u001b[0m\n\u001b[0;32m    263\u001b[0m \u001b[38;5;28;01mtry\u001b[39;00m:\n\u001b[0;32m    264\u001b[0m     sock \u001b[38;5;241m=\u001b[39m \u001b[38;5;28mself\u001b[39m\u001b[38;5;241m.\u001b[39mretry\u001b[38;5;241m.\u001b[39mcall_with_retry(\n\u001b[1;32m--> 265\u001b[0m         \u001b[38;5;28;01mlambda\u001b[39;00m: \u001b[38;5;28mself\u001b[39m\u001b[38;5;241m.\u001b[39m_connect(), \u001b[38;5;28;01mlambda\u001b[39;00m error: \u001b[38;5;28mself\u001b[39m\u001b[38;5;241m.\u001b[39mdisconnect(error)\n\u001b[0;32m    266\u001b[0m     )\n\u001b[0;32m    267\u001b[0m \u001b[38;5;28;01mexcept\u001b[39;00m socket\u001b[38;5;241m.\u001b[39mtimeout:\n",
      "File \u001b[1;32m~\\AppData\\Roaming\\Python\\Python311\\site-packages\\redis\\connection.py:627\u001b[0m, in \u001b[0;36mConnection._connect\u001b[1;34m(self)\u001b[0m\n\u001b[0;32m    626\u001b[0m \u001b[38;5;28;01mif\u001b[39;00m err \u001b[38;5;129;01mis\u001b[39;00m \u001b[38;5;129;01mnot\u001b[39;00m \u001b[38;5;28;01mNone\u001b[39;00m:\n\u001b[1;32m--> 627\u001b[0m     \u001b[38;5;28;01mraise\u001b[39;00m err\n\u001b[0;32m    628\u001b[0m \u001b[38;5;28;01mraise\u001b[39;00m \u001b[38;5;167;01mOSError\u001b[39;00m(\u001b[38;5;124m\"\u001b[39m\u001b[38;5;124msocket.getaddrinfo returned an empty list\u001b[39m\u001b[38;5;124m\"\u001b[39m)\n",
      "File \u001b[1;32m~\\AppData\\Roaming\\Python\\Python311\\site-packages\\redis\\connection.py:615\u001b[0m, in \u001b[0;36mConnection._connect\u001b[1;34m(self)\u001b[0m\n\u001b[0;32m    614\u001b[0m \u001b[38;5;66;03m# connect\u001b[39;00m\n\u001b[1;32m--> 615\u001b[0m sock\u001b[38;5;241m.\u001b[39mconnect(socket_address)\n\u001b[0;32m    617\u001b[0m \u001b[38;5;66;03m# set the socket_timeout now that we're connected\u001b[39;00m\n",
      "\u001b[1;31mConnectionRefusedError\u001b[0m: [WinError 10061] No connection could be made because the target machine actively refused it",
      "\nDuring handling of the above exception, another exception occurred:\n",
      "\u001b[1;31mConnectionError\u001b[0m                           Traceback (most recent call last)",
      "Cell \u001b[1;32mIn[6], line 1\u001b[0m\n\u001b[1;32m----> 1\u001b[0m conn\u001b[38;5;241m.\u001b[39mhmset(\u001b[38;5;124m'\u001b[39m\u001b[38;5;124mtest\u001b[39m\u001b[38;5;124m'\u001b[39m, {\u001b[38;5;124m'\u001b[39m\u001b[38;5;124mcount\u001b[39m\u001b[38;5;124m'\u001b[39m: \u001b[38;5;241m1\u001b[39m, \u001b[38;5;124m'\u001b[39m\u001b[38;5;124mname\u001b[39m\u001b[38;5;124m'\u001b[39m: \u001b[38;5;124m'\u001b[39m\u001b[38;5;124mFester Bestertester\u001b[39m\u001b[38;5;124m'\u001b[39m})\n",
      "File \u001b[1;32m~\\AppData\\Roaming\\Python\\Python311\\site-packages\\redis\\commands\\core.py:5048\u001b[0m, in \u001b[0;36mHashCommands.hmset\u001b[1;34m(self, name, mapping)\u001b[0m\n\u001b[0;32m   5046\u001b[0m \u001b[38;5;28;01mfor\u001b[39;00m pair \u001b[38;5;129;01min\u001b[39;00m mapping\u001b[38;5;241m.\u001b[39mitems():\n\u001b[0;32m   5047\u001b[0m     items\u001b[38;5;241m.\u001b[39mextend(pair)\n\u001b[1;32m-> 5048\u001b[0m \u001b[38;5;28;01mreturn\u001b[39;00m \u001b[38;5;28mself\u001b[39m\u001b[38;5;241m.\u001b[39mexecute_command(\u001b[38;5;124m\"\u001b[39m\u001b[38;5;124mHMSET\u001b[39m\u001b[38;5;124m\"\u001b[39m, name, \u001b[38;5;241m*\u001b[39mitems)\n",
      "File \u001b[1;32m~\\AppData\\Roaming\\Python\\Python311\\site-packages\\redis\\client.py:533\u001b[0m, in \u001b[0;36mRedis.execute_command\u001b[1;34m(self, *args, **options)\u001b[0m\n\u001b[0;32m    531\u001b[0m pool \u001b[38;5;241m=\u001b[39m \u001b[38;5;28mself\u001b[39m\u001b[38;5;241m.\u001b[39mconnection_pool\n\u001b[0;32m    532\u001b[0m command_name \u001b[38;5;241m=\u001b[39m args[\u001b[38;5;241m0\u001b[39m]\n\u001b[1;32m--> 533\u001b[0m conn \u001b[38;5;241m=\u001b[39m \u001b[38;5;28mself\u001b[39m\u001b[38;5;241m.\u001b[39mconnection \u001b[38;5;129;01mor\u001b[39;00m pool\u001b[38;5;241m.\u001b[39mget_connection(command_name, \u001b[38;5;241m*\u001b[39m\u001b[38;5;241m*\u001b[39moptions)\n\u001b[0;32m    535\u001b[0m \u001b[38;5;28;01mtry\u001b[39;00m:\n\u001b[0;32m    536\u001b[0m     \u001b[38;5;28;01mreturn\u001b[39;00m conn\u001b[38;5;241m.\u001b[39mretry\u001b[38;5;241m.\u001b[39mcall_with_retry(\n\u001b[0;32m    537\u001b[0m         \u001b[38;5;28;01mlambda\u001b[39;00m: \u001b[38;5;28mself\u001b[39m\u001b[38;5;241m.\u001b[39m_send_command_parse_response(\n\u001b[0;32m    538\u001b[0m             conn, command_name, \u001b[38;5;241m*\u001b[39margs, \u001b[38;5;241m*\u001b[39m\u001b[38;5;241m*\u001b[39moptions\n\u001b[0;32m    539\u001b[0m         ),\n\u001b[0;32m    540\u001b[0m         \u001b[38;5;28;01mlambda\u001b[39;00m error: \u001b[38;5;28mself\u001b[39m\u001b[38;5;241m.\u001b[39m_disconnect_raise(conn, error),\n\u001b[0;32m    541\u001b[0m     )\n",
      "File \u001b[1;32m~\\AppData\\Roaming\\Python\\Python311\\site-packages\\redis\\connection.py:1086\u001b[0m, in \u001b[0;36mConnectionPool.get_connection\u001b[1;34m(self, command_name, *keys, **options)\u001b[0m\n\u001b[0;32m   1082\u001b[0m     \u001b[38;5;28mself\u001b[39m\u001b[38;5;241m.\u001b[39m_in_use_connections\u001b[38;5;241m.\u001b[39madd(connection)\n\u001b[0;32m   1084\u001b[0m \u001b[38;5;28;01mtry\u001b[39;00m:\n\u001b[0;32m   1085\u001b[0m     \u001b[38;5;66;03m# ensure this connection is connected to Redis\u001b[39;00m\n\u001b[1;32m-> 1086\u001b[0m     connection\u001b[38;5;241m.\u001b[39mconnect()\n\u001b[0;32m   1087\u001b[0m     \u001b[38;5;66;03m# connections that the pool provides should be ready to send\u001b[39;00m\n\u001b[0;32m   1088\u001b[0m     \u001b[38;5;66;03m# a command. if not, the connection was either returned to the\u001b[39;00m\n\u001b[0;32m   1089\u001b[0m     \u001b[38;5;66;03m# pool before all data has been read or the socket has been\u001b[39;00m\n\u001b[0;32m   1090\u001b[0m     \u001b[38;5;66;03m# closed. either way, reconnect and verify everything is good.\u001b[39;00m\n\u001b[0;32m   1091\u001b[0m     \u001b[38;5;28;01mtry\u001b[39;00m:\n",
      "File \u001b[1;32m~\\AppData\\Roaming\\Python\\Python311\\site-packages\\redis\\connection.py:270\u001b[0m, in \u001b[0;36mAbstractConnection.connect\u001b[1;34m(self)\u001b[0m\n\u001b[0;32m    268\u001b[0m     \u001b[38;5;28;01mraise\u001b[39;00m \u001b[38;5;167;01mTimeoutError\u001b[39;00m(\u001b[38;5;124m\"\u001b[39m\u001b[38;5;124mTimeout connecting to server\u001b[39m\u001b[38;5;124m\"\u001b[39m)\n\u001b[0;32m    269\u001b[0m \u001b[38;5;28;01mexcept\u001b[39;00m \u001b[38;5;167;01mOSError\u001b[39;00m \u001b[38;5;28;01mas\u001b[39;00m e:\n\u001b[1;32m--> 270\u001b[0m     \u001b[38;5;28;01mraise\u001b[39;00m \u001b[38;5;167;01mConnectionError\u001b[39;00m(\u001b[38;5;28mself\u001b[39m\u001b[38;5;241m.\u001b[39m_error_message(e))\n\u001b[0;32m    272\u001b[0m \u001b[38;5;28mself\u001b[39m\u001b[38;5;241m.\u001b[39m_sock \u001b[38;5;241m=\u001b[39m sock\n\u001b[0;32m    273\u001b[0m \u001b[38;5;28;01mtry\u001b[39;00m:\n",
      "\u001b[1;31mConnectionError\u001b[0m: Error 10061 connecting to localhost:6379. No connection could be made because the target machine actively refused it."
     ]
    }
   ],
   "source": [
    "conn.hmset('test', {'count': 1, 'name': 'Fester Bestertester'})"
   ]
  },
  {
   "cell_type": "code",
   "execution_count": 8,
   "id": "9da5f7ec",
   "metadata": {},
   "outputs": [
    {
     "ename": "ConnectionError",
     "evalue": "Error 10061 connecting to localhost:6379. No connection could be made because the target machine actively refused it.",
     "output_type": "error",
     "traceback": [
      "\u001b[1;31m---------------------------------------------------------------------------\u001b[0m",
      "\u001b[1;31mConnectionRefusedError\u001b[0m                    Traceback (most recent call last)",
      "File \u001b[1;32m~\\AppData\\Roaming\\Python\\Python311\\site-packages\\redis\\connection.py:264\u001b[0m, in \u001b[0;36mAbstractConnection.connect\u001b[1;34m(self)\u001b[0m\n\u001b[0;32m    263\u001b[0m \u001b[38;5;28;01mtry\u001b[39;00m:\n\u001b[1;32m--> 264\u001b[0m     sock \u001b[38;5;241m=\u001b[39m \u001b[38;5;28mself\u001b[39m\u001b[38;5;241m.\u001b[39mretry\u001b[38;5;241m.\u001b[39mcall_with_retry(\n\u001b[0;32m    265\u001b[0m         \u001b[38;5;28;01mlambda\u001b[39;00m: \u001b[38;5;28mself\u001b[39m\u001b[38;5;241m.\u001b[39m_connect(), \u001b[38;5;28;01mlambda\u001b[39;00m error: \u001b[38;5;28mself\u001b[39m\u001b[38;5;241m.\u001b[39mdisconnect(error)\n\u001b[0;32m    266\u001b[0m     )\n\u001b[0;32m    267\u001b[0m \u001b[38;5;28;01mexcept\u001b[39;00m socket\u001b[38;5;241m.\u001b[39mtimeout:\n",
      "File \u001b[1;32m~\\AppData\\Roaming\\Python\\Python311\\site-packages\\redis\\retry.py:46\u001b[0m, in \u001b[0;36mRetry.call_with_retry\u001b[1;34m(self, do, fail)\u001b[0m\n\u001b[0;32m     45\u001b[0m \u001b[38;5;28;01mtry\u001b[39;00m:\n\u001b[1;32m---> 46\u001b[0m     \u001b[38;5;28;01mreturn\u001b[39;00m do()\n\u001b[0;32m     47\u001b[0m \u001b[38;5;28;01mexcept\u001b[39;00m \u001b[38;5;28mself\u001b[39m\u001b[38;5;241m.\u001b[39m_supported_errors \u001b[38;5;28;01mas\u001b[39;00m error:\n",
      "File \u001b[1;32m~\\AppData\\Roaming\\Python\\Python311\\site-packages\\redis\\connection.py:265\u001b[0m, in \u001b[0;36mAbstractConnection.connect.<locals>.<lambda>\u001b[1;34m()\u001b[0m\n\u001b[0;32m    263\u001b[0m \u001b[38;5;28;01mtry\u001b[39;00m:\n\u001b[0;32m    264\u001b[0m     sock \u001b[38;5;241m=\u001b[39m \u001b[38;5;28mself\u001b[39m\u001b[38;5;241m.\u001b[39mretry\u001b[38;5;241m.\u001b[39mcall_with_retry(\n\u001b[1;32m--> 265\u001b[0m         \u001b[38;5;28;01mlambda\u001b[39;00m: \u001b[38;5;28mself\u001b[39m\u001b[38;5;241m.\u001b[39m_connect(), \u001b[38;5;28;01mlambda\u001b[39;00m error: \u001b[38;5;28mself\u001b[39m\u001b[38;5;241m.\u001b[39mdisconnect(error)\n\u001b[0;32m    266\u001b[0m     )\n\u001b[0;32m    267\u001b[0m \u001b[38;5;28;01mexcept\u001b[39;00m socket\u001b[38;5;241m.\u001b[39mtimeout:\n",
      "File \u001b[1;32m~\\AppData\\Roaming\\Python\\Python311\\site-packages\\redis\\connection.py:627\u001b[0m, in \u001b[0;36mConnection._connect\u001b[1;34m(self)\u001b[0m\n\u001b[0;32m    626\u001b[0m \u001b[38;5;28;01mif\u001b[39;00m err \u001b[38;5;129;01mis\u001b[39;00m \u001b[38;5;129;01mnot\u001b[39;00m \u001b[38;5;28;01mNone\u001b[39;00m:\n\u001b[1;32m--> 627\u001b[0m     \u001b[38;5;28;01mraise\u001b[39;00m err\n\u001b[0;32m    628\u001b[0m \u001b[38;5;28;01mraise\u001b[39;00m \u001b[38;5;167;01mOSError\u001b[39;00m(\u001b[38;5;124m\"\u001b[39m\u001b[38;5;124msocket.getaddrinfo returned an empty list\u001b[39m\u001b[38;5;124m\"\u001b[39m)\n",
      "File \u001b[1;32m~\\AppData\\Roaming\\Python\\Python311\\site-packages\\redis\\connection.py:615\u001b[0m, in \u001b[0;36mConnection._connect\u001b[1;34m(self)\u001b[0m\n\u001b[0;32m    614\u001b[0m \u001b[38;5;66;03m# connect\u001b[39;00m\n\u001b[1;32m--> 615\u001b[0m sock\u001b[38;5;241m.\u001b[39mconnect(socket_address)\n\u001b[0;32m    617\u001b[0m \u001b[38;5;66;03m# set the socket_timeout now that we're connected\u001b[39;00m\n",
      "\u001b[1;31mConnectionRefusedError\u001b[0m: [WinError 10061] No connection could be made because the target machine actively refused it",
      "\nDuring handling of the above exception, another exception occurred:\n",
      "\u001b[1;31mConnectionError\u001b[0m                           Traceback (most recent call last)",
      "Cell \u001b[1;32mIn[8], line 1\u001b[0m\n\u001b[1;32m----> 1\u001b[0m conn\u001b[38;5;241m.\u001b[39mhgetall(\u001b[38;5;124m'\u001b[39m\u001b[38;5;124mtest\u001b[39m\u001b[38;5;124m'\u001b[39m)\n",
      "File \u001b[1;32m~\\AppData\\Roaming\\Python\\Python311\\site-packages\\redis\\commands\\core.py:4954\u001b[0m, in \u001b[0;36mHashCommands.hgetall\u001b[1;34m(self, name)\u001b[0m\n\u001b[0;32m   4948\u001b[0m \u001b[38;5;28;01mdef\u001b[39;00m \u001b[38;5;21mhgetall\u001b[39m(\u001b[38;5;28mself\u001b[39m, name: \u001b[38;5;28mstr\u001b[39m) \u001b[38;5;241m-\u001b[39m\u001b[38;5;241m>\u001b[39m Union[Awaitable[\u001b[38;5;28mdict\u001b[39m], \u001b[38;5;28mdict\u001b[39m]:\n\u001b[0;32m   4949\u001b[0m \u001b[38;5;250m    \u001b[39m\u001b[38;5;124;03m\"\"\"\u001b[39;00m\n\u001b[0;32m   4950\u001b[0m \u001b[38;5;124;03m    Return a Python dict of the hash's name/value pairs\u001b[39;00m\n\u001b[0;32m   4951\u001b[0m \n\u001b[0;32m   4952\u001b[0m \u001b[38;5;124;03m    For more information see https://redis.io/commands/hgetall\u001b[39;00m\n\u001b[0;32m   4953\u001b[0m \u001b[38;5;124;03m    \"\"\"\u001b[39;00m\n\u001b[1;32m-> 4954\u001b[0m     \u001b[38;5;28;01mreturn\u001b[39;00m \u001b[38;5;28mself\u001b[39m\u001b[38;5;241m.\u001b[39mexecute_command(\u001b[38;5;124m\"\u001b[39m\u001b[38;5;124mHGETALL\u001b[39m\u001b[38;5;124m\"\u001b[39m, name)\n",
      "File \u001b[1;32m~\\AppData\\Roaming\\Python\\Python311\\site-packages\\redis\\client.py:533\u001b[0m, in \u001b[0;36mRedis.execute_command\u001b[1;34m(self, *args, **options)\u001b[0m\n\u001b[0;32m    531\u001b[0m pool \u001b[38;5;241m=\u001b[39m \u001b[38;5;28mself\u001b[39m\u001b[38;5;241m.\u001b[39mconnection_pool\n\u001b[0;32m    532\u001b[0m command_name \u001b[38;5;241m=\u001b[39m args[\u001b[38;5;241m0\u001b[39m]\n\u001b[1;32m--> 533\u001b[0m conn \u001b[38;5;241m=\u001b[39m \u001b[38;5;28mself\u001b[39m\u001b[38;5;241m.\u001b[39mconnection \u001b[38;5;129;01mor\u001b[39;00m pool\u001b[38;5;241m.\u001b[39mget_connection(command_name, \u001b[38;5;241m*\u001b[39m\u001b[38;5;241m*\u001b[39moptions)\n\u001b[0;32m    535\u001b[0m \u001b[38;5;28;01mtry\u001b[39;00m:\n\u001b[0;32m    536\u001b[0m     \u001b[38;5;28;01mreturn\u001b[39;00m conn\u001b[38;5;241m.\u001b[39mretry\u001b[38;5;241m.\u001b[39mcall_with_retry(\n\u001b[0;32m    537\u001b[0m         \u001b[38;5;28;01mlambda\u001b[39;00m: \u001b[38;5;28mself\u001b[39m\u001b[38;5;241m.\u001b[39m_send_command_parse_response(\n\u001b[0;32m    538\u001b[0m             conn, command_name, \u001b[38;5;241m*\u001b[39margs, \u001b[38;5;241m*\u001b[39m\u001b[38;5;241m*\u001b[39moptions\n\u001b[0;32m    539\u001b[0m         ),\n\u001b[0;32m    540\u001b[0m         \u001b[38;5;28;01mlambda\u001b[39;00m error: \u001b[38;5;28mself\u001b[39m\u001b[38;5;241m.\u001b[39m_disconnect_raise(conn, error),\n\u001b[0;32m    541\u001b[0m     )\n",
      "File \u001b[1;32m~\\AppData\\Roaming\\Python\\Python311\\site-packages\\redis\\connection.py:1086\u001b[0m, in \u001b[0;36mConnectionPool.get_connection\u001b[1;34m(self, command_name, *keys, **options)\u001b[0m\n\u001b[0;32m   1082\u001b[0m     \u001b[38;5;28mself\u001b[39m\u001b[38;5;241m.\u001b[39m_in_use_connections\u001b[38;5;241m.\u001b[39madd(connection)\n\u001b[0;32m   1084\u001b[0m \u001b[38;5;28;01mtry\u001b[39;00m:\n\u001b[0;32m   1085\u001b[0m     \u001b[38;5;66;03m# ensure this connection is connected to Redis\u001b[39;00m\n\u001b[1;32m-> 1086\u001b[0m     connection\u001b[38;5;241m.\u001b[39mconnect()\n\u001b[0;32m   1087\u001b[0m     \u001b[38;5;66;03m# connections that the pool provides should be ready to send\u001b[39;00m\n\u001b[0;32m   1088\u001b[0m     \u001b[38;5;66;03m# a command. if not, the connection was either returned to the\u001b[39;00m\n\u001b[0;32m   1089\u001b[0m     \u001b[38;5;66;03m# pool before all data has been read or the socket has been\u001b[39;00m\n\u001b[0;32m   1090\u001b[0m     \u001b[38;5;66;03m# closed. either way, reconnect and verify everything is good.\u001b[39;00m\n\u001b[0;32m   1091\u001b[0m     \u001b[38;5;28;01mtry\u001b[39;00m:\n",
      "File \u001b[1;32m~\\AppData\\Roaming\\Python\\Python311\\site-packages\\redis\\connection.py:270\u001b[0m, in \u001b[0;36mAbstractConnection.connect\u001b[1;34m(self)\u001b[0m\n\u001b[0;32m    268\u001b[0m     \u001b[38;5;28;01mraise\u001b[39;00m \u001b[38;5;167;01mTimeoutError\u001b[39;00m(\u001b[38;5;124m\"\u001b[39m\u001b[38;5;124mTimeout connecting to server\u001b[39m\u001b[38;5;124m\"\u001b[39m)\n\u001b[0;32m    269\u001b[0m \u001b[38;5;28;01mexcept\u001b[39;00m \u001b[38;5;167;01mOSError\u001b[39;00m \u001b[38;5;28;01mas\u001b[39;00m e:\n\u001b[1;32m--> 270\u001b[0m     \u001b[38;5;28;01mraise\u001b[39;00m \u001b[38;5;167;01mConnectionError\u001b[39;00m(\u001b[38;5;28mself\u001b[39m\u001b[38;5;241m.\u001b[39m_error_message(e))\n\u001b[0;32m    272\u001b[0m \u001b[38;5;28mself\u001b[39m\u001b[38;5;241m.\u001b[39m_sock \u001b[38;5;241m=\u001b[39m sock\n\u001b[0;32m    273\u001b[0m \u001b[38;5;28;01mtry\u001b[39;00m:\n",
      "\u001b[1;31mConnectionError\u001b[0m: Error 10061 connecting to localhost:6379. No connection could be made because the target machine actively refused it."
     ]
    }
   ],
   "source": [
    "conn.hgetall('test')"
   ]
  },
  {
   "cell_type": "markdown",
   "id": "38ff92bc",
   "metadata": {},
   "source": [
    "10> Increment the count field of test and print it."
   ]
  },
  {
   "cell_type": "code",
   "execution_count": 7,
   "id": "cc581829",
   "metadata": {},
   "outputs": [
    {
     "ename": "ConnectionError",
     "evalue": "Error 10061 connecting to localhost:6379. No connection could be made because the target machine actively refused it.",
     "output_type": "error",
     "traceback": [
      "\u001b[1;31m---------------------------------------------------------------------------\u001b[0m",
      "\u001b[1;31mConnectionRefusedError\u001b[0m                    Traceback (most recent call last)",
      "File \u001b[1;32m~\\AppData\\Roaming\\Python\\Python311\\site-packages\\redis\\connection.py:264\u001b[0m, in \u001b[0;36mAbstractConnection.connect\u001b[1;34m(self)\u001b[0m\n\u001b[0;32m    263\u001b[0m \u001b[38;5;28;01mtry\u001b[39;00m:\n\u001b[1;32m--> 264\u001b[0m     sock \u001b[38;5;241m=\u001b[39m \u001b[38;5;28mself\u001b[39m\u001b[38;5;241m.\u001b[39mretry\u001b[38;5;241m.\u001b[39mcall_with_retry(\n\u001b[0;32m    265\u001b[0m         \u001b[38;5;28;01mlambda\u001b[39;00m: \u001b[38;5;28mself\u001b[39m\u001b[38;5;241m.\u001b[39m_connect(), \u001b[38;5;28;01mlambda\u001b[39;00m error: \u001b[38;5;28mself\u001b[39m\u001b[38;5;241m.\u001b[39mdisconnect(error)\n\u001b[0;32m    266\u001b[0m     )\n\u001b[0;32m    267\u001b[0m \u001b[38;5;28;01mexcept\u001b[39;00m socket\u001b[38;5;241m.\u001b[39mtimeout:\n",
      "File \u001b[1;32m~\\AppData\\Roaming\\Python\\Python311\\site-packages\\redis\\retry.py:46\u001b[0m, in \u001b[0;36mRetry.call_with_retry\u001b[1;34m(self, do, fail)\u001b[0m\n\u001b[0;32m     45\u001b[0m \u001b[38;5;28;01mtry\u001b[39;00m:\n\u001b[1;32m---> 46\u001b[0m     \u001b[38;5;28;01mreturn\u001b[39;00m do()\n\u001b[0;32m     47\u001b[0m \u001b[38;5;28;01mexcept\u001b[39;00m \u001b[38;5;28mself\u001b[39m\u001b[38;5;241m.\u001b[39m_supported_errors \u001b[38;5;28;01mas\u001b[39;00m error:\n",
      "File \u001b[1;32m~\\AppData\\Roaming\\Python\\Python311\\site-packages\\redis\\connection.py:265\u001b[0m, in \u001b[0;36mAbstractConnection.connect.<locals>.<lambda>\u001b[1;34m()\u001b[0m\n\u001b[0;32m    263\u001b[0m \u001b[38;5;28;01mtry\u001b[39;00m:\n\u001b[0;32m    264\u001b[0m     sock \u001b[38;5;241m=\u001b[39m \u001b[38;5;28mself\u001b[39m\u001b[38;5;241m.\u001b[39mretry\u001b[38;5;241m.\u001b[39mcall_with_retry(\n\u001b[1;32m--> 265\u001b[0m         \u001b[38;5;28;01mlambda\u001b[39;00m: \u001b[38;5;28mself\u001b[39m\u001b[38;5;241m.\u001b[39m_connect(), \u001b[38;5;28;01mlambda\u001b[39;00m error: \u001b[38;5;28mself\u001b[39m\u001b[38;5;241m.\u001b[39mdisconnect(error)\n\u001b[0;32m    266\u001b[0m     )\n\u001b[0;32m    267\u001b[0m \u001b[38;5;28;01mexcept\u001b[39;00m socket\u001b[38;5;241m.\u001b[39mtimeout:\n",
      "File \u001b[1;32m~\\AppData\\Roaming\\Python\\Python311\\site-packages\\redis\\connection.py:627\u001b[0m, in \u001b[0;36mConnection._connect\u001b[1;34m(self)\u001b[0m\n\u001b[0;32m    626\u001b[0m \u001b[38;5;28;01mif\u001b[39;00m err \u001b[38;5;129;01mis\u001b[39;00m \u001b[38;5;129;01mnot\u001b[39;00m \u001b[38;5;28;01mNone\u001b[39;00m:\n\u001b[1;32m--> 627\u001b[0m     \u001b[38;5;28;01mraise\u001b[39;00m err\n\u001b[0;32m    628\u001b[0m \u001b[38;5;28;01mraise\u001b[39;00m \u001b[38;5;167;01mOSError\u001b[39;00m(\u001b[38;5;124m\"\u001b[39m\u001b[38;5;124msocket.getaddrinfo returned an empty list\u001b[39m\u001b[38;5;124m\"\u001b[39m)\n",
      "File \u001b[1;32m~\\AppData\\Roaming\\Python\\Python311\\site-packages\\redis\\connection.py:615\u001b[0m, in \u001b[0;36mConnection._connect\u001b[1;34m(self)\u001b[0m\n\u001b[0;32m    614\u001b[0m \u001b[38;5;66;03m# connect\u001b[39;00m\n\u001b[1;32m--> 615\u001b[0m sock\u001b[38;5;241m.\u001b[39mconnect(socket_address)\n\u001b[0;32m    617\u001b[0m \u001b[38;5;66;03m# set the socket_timeout now that we're connected\u001b[39;00m\n",
      "\u001b[1;31mConnectionRefusedError\u001b[0m: [WinError 10061] No connection could be made because the target machine actively refused it",
      "\nDuring handling of the above exception, another exception occurred:\n",
      "\u001b[1;31mConnectionError\u001b[0m                           Traceback (most recent call last)",
      "Cell \u001b[1;32mIn[7], line 1\u001b[0m\n\u001b[1;32m----> 1\u001b[0m conn\u001b[38;5;241m.\u001b[39mhincrby(\u001b[38;5;124m'\u001b[39m\u001b[38;5;124mtest\u001b[39m\u001b[38;5;124m'\u001b[39m, \u001b[38;5;124m'\u001b[39m\u001b[38;5;124mcount\u001b[39m\u001b[38;5;124m'\u001b[39m, \u001b[38;5;241m3\u001b[39m)\n",
      "File \u001b[1;32m~\\AppData\\Roaming\\Python\\Python311\\site-packages\\redis\\commands\\core.py:4964\u001b[0m, in \u001b[0;36mHashCommands.hincrby\u001b[1;34m(self, name, key, amount)\u001b[0m\n\u001b[0;32m   4956\u001b[0m \u001b[38;5;28;01mdef\u001b[39;00m \u001b[38;5;21mhincrby\u001b[39m(\n\u001b[0;32m   4957\u001b[0m     \u001b[38;5;28mself\u001b[39m, name: \u001b[38;5;28mstr\u001b[39m, key: \u001b[38;5;28mstr\u001b[39m, amount: \u001b[38;5;28mint\u001b[39m \u001b[38;5;241m=\u001b[39m \u001b[38;5;241m1\u001b[39m\n\u001b[0;32m   4958\u001b[0m ) \u001b[38;5;241m-\u001b[39m\u001b[38;5;241m>\u001b[39m Union[Awaitable[\u001b[38;5;28mint\u001b[39m], \u001b[38;5;28mint\u001b[39m]:\n\u001b[0;32m   4959\u001b[0m \u001b[38;5;250m    \u001b[39m\u001b[38;5;124;03m\"\"\"\u001b[39;00m\n\u001b[0;32m   4960\u001b[0m \u001b[38;5;124;03m    Increment the value of ``key`` in hash ``name`` by ``amount``\u001b[39;00m\n\u001b[0;32m   4961\u001b[0m \n\u001b[0;32m   4962\u001b[0m \u001b[38;5;124;03m    For more information see https://redis.io/commands/hincrby\u001b[39;00m\n\u001b[0;32m   4963\u001b[0m \u001b[38;5;124;03m    \"\"\"\u001b[39;00m\n\u001b[1;32m-> 4964\u001b[0m     \u001b[38;5;28;01mreturn\u001b[39;00m \u001b[38;5;28mself\u001b[39m\u001b[38;5;241m.\u001b[39mexecute_command(\u001b[38;5;124m\"\u001b[39m\u001b[38;5;124mHINCRBY\u001b[39m\u001b[38;5;124m\"\u001b[39m, name, key, amount)\n",
      "File \u001b[1;32m~\\AppData\\Roaming\\Python\\Python311\\site-packages\\redis\\client.py:533\u001b[0m, in \u001b[0;36mRedis.execute_command\u001b[1;34m(self, *args, **options)\u001b[0m\n\u001b[0;32m    531\u001b[0m pool \u001b[38;5;241m=\u001b[39m \u001b[38;5;28mself\u001b[39m\u001b[38;5;241m.\u001b[39mconnection_pool\n\u001b[0;32m    532\u001b[0m command_name \u001b[38;5;241m=\u001b[39m args[\u001b[38;5;241m0\u001b[39m]\n\u001b[1;32m--> 533\u001b[0m conn \u001b[38;5;241m=\u001b[39m \u001b[38;5;28mself\u001b[39m\u001b[38;5;241m.\u001b[39mconnection \u001b[38;5;129;01mor\u001b[39;00m pool\u001b[38;5;241m.\u001b[39mget_connection(command_name, \u001b[38;5;241m*\u001b[39m\u001b[38;5;241m*\u001b[39moptions)\n\u001b[0;32m    535\u001b[0m \u001b[38;5;28;01mtry\u001b[39;00m:\n\u001b[0;32m    536\u001b[0m     \u001b[38;5;28;01mreturn\u001b[39;00m conn\u001b[38;5;241m.\u001b[39mretry\u001b[38;5;241m.\u001b[39mcall_with_retry(\n\u001b[0;32m    537\u001b[0m         \u001b[38;5;28;01mlambda\u001b[39;00m: \u001b[38;5;28mself\u001b[39m\u001b[38;5;241m.\u001b[39m_send_command_parse_response(\n\u001b[0;32m    538\u001b[0m             conn, command_name, \u001b[38;5;241m*\u001b[39margs, \u001b[38;5;241m*\u001b[39m\u001b[38;5;241m*\u001b[39moptions\n\u001b[0;32m    539\u001b[0m         ),\n\u001b[0;32m    540\u001b[0m         \u001b[38;5;28;01mlambda\u001b[39;00m error: \u001b[38;5;28mself\u001b[39m\u001b[38;5;241m.\u001b[39m_disconnect_raise(conn, error),\n\u001b[0;32m    541\u001b[0m     )\n",
      "File \u001b[1;32m~\\AppData\\Roaming\\Python\\Python311\\site-packages\\redis\\connection.py:1086\u001b[0m, in \u001b[0;36mConnectionPool.get_connection\u001b[1;34m(self, command_name, *keys, **options)\u001b[0m\n\u001b[0;32m   1082\u001b[0m     \u001b[38;5;28mself\u001b[39m\u001b[38;5;241m.\u001b[39m_in_use_connections\u001b[38;5;241m.\u001b[39madd(connection)\n\u001b[0;32m   1084\u001b[0m \u001b[38;5;28;01mtry\u001b[39;00m:\n\u001b[0;32m   1085\u001b[0m     \u001b[38;5;66;03m# ensure this connection is connected to Redis\u001b[39;00m\n\u001b[1;32m-> 1086\u001b[0m     connection\u001b[38;5;241m.\u001b[39mconnect()\n\u001b[0;32m   1087\u001b[0m     \u001b[38;5;66;03m# connections that the pool provides should be ready to send\u001b[39;00m\n\u001b[0;32m   1088\u001b[0m     \u001b[38;5;66;03m# a command. if not, the connection was either returned to the\u001b[39;00m\n\u001b[0;32m   1089\u001b[0m     \u001b[38;5;66;03m# pool before all data has been read or the socket has been\u001b[39;00m\n\u001b[0;32m   1090\u001b[0m     \u001b[38;5;66;03m# closed. either way, reconnect and verify everything is good.\u001b[39;00m\n\u001b[0;32m   1091\u001b[0m     \u001b[38;5;28;01mtry\u001b[39;00m:\n",
      "File \u001b[1;32m~\\AppData\\Roaming\\Python\\Python311\\site-packages\\redis\\connection.py:270\u001b[0m, in \u001b[0;36mAbstractConnection.connect\u001b[1;34m(self)\u001b[0m\n\u001b[0;32m    268\u001b[0m     \u001b[38;5;28;01mraise\u001b[39;00m \u001b[38;5;167;01mTimeoutError\u001b[39;00m(\u001b[38;5;124m\"\u001b[39m\u001b[38;5;124mTimeout connecting to server\u001b[39m\u001b[38;5;124m\"\u001b[39m)\n\u001b[0;32m    269\u001b[0m \u001b[38;5;28;01mexcept\u001b[39;00m \u001b[38;5;167;01mOSError\u001b[39;00m \u001b[38;5;28;01mas\u001b[39;00m e:\n\u001b[1;32m--> 270\u001b[0m     \u001b[38;5;28;01mraise\u001b[39;00m \u001b[38;5;167;01mConnectionError\u001b[39;00m(\u001b[38;5;28mself\u001b[39m\u001b[38;5;241m.\u001b[39m_error_message(e))\n\u001b[0;32m    272\u001b[0m \u001b[38;5;28mself\u001b[39m\u001b[38;5;241m.\u001b[39m_sock \u001b[38;5;241m=\u001b[39m sock\n\u001b[0;32m    273\u001b[0m \u001b[38;5;28;01mtry\u001b[39;00m:\n",
      "\u001b[1;31mConnectionError\u001b[0m: Error 10061 connecting to localhost:6379. No connection could be made because the target machine actively refused it."
     ]
    }
   ],
   "source": [
    "conn.hincrby('test', 'count', 3)\n"
   ]
  },
  {
   "cell_type": "code",
   "execution_count": 28,
   "id": "9d48d694",
   "metadata": {},
   "outputs": [
    {
     "ename": "AttributeError",
     "evalue": "'Engine' object has no attribute 'hget'",
     "output_type": "error",
     "traceback": [
      "\u001b[1;31m---------------------------------------------------------------------------\u001b[0m",
      "\u001b[1;31mAttributeError\u001b[0m                            Traceback (most recent call last)",
      "Cell \u001b[1;32mIn[28], line 1\u001b[0m\n\u001b[1;32m----> 1\u001b[0m conn\u001b[38;5;241m.\u001b[39mhget(\u001b[38;5;124m'\u001b[39m\u001b[38;5;124mtest\u001b[39m\u001b[38;5;124m'\u001b[39m, \u001b[38;5;124m'\u001b[39m\u001b[38;5;124mcount\u001b[39m\u001b[38;5;124m'\u001b[39m)\n",
      "\u001b[1;31mAttributeError\u001b[0m: 'Engine' object has no attribute 'hget'"
     ]
    }
   ],
   "source": [
    "conn.hget('test', 'count')"
   ]
  },
  {
   "cell_type": "markdown",
   "id": "d4d2277b",
   "metadata": {},
   "source": [
    "10. Increment the count field of test and print it."
   ]
  },
  {
   "cell_type": "code",
   "execution_count": 29,
   "id": "4281eff1",
   "metadata": {},
   "outputs": [
    {
     "ename": "AttributeError",
     "evalue": "'Engine' object has no attribute 'hincrby'",
     "output_type": "error",
     "traceback": [
      "\u001b[1;31m---------------------------------------------------------------------------\u001b[0m",
      "\u001b[1;31mAttributeError\u001b[0m                            Traceback (most recent call last)",
      "Cell \u001b[1;32mIn[29], line 1\u001b[0m\n\u001b[1;32m----> 1\u001b[0m conn\u001b[38;5;241m.\u001b[39mhincrby(\u001b[38;5;124m'\u001b[39m\u001b[38;5;124mtest\u001b[39m\u001b[38;5;124m'\u001b[39m, \u001b[38;5;124m'\u001b[39m\u001b[38;5;124mcount\u001b[39m\u001b[38;5;124m'\u001b[39m, \u001b[38;5;241m3\u001b[39m)\n",
      "\u001b[1;31mAttributeError\u001b[0m: 'Engine' object has no attribute 'hincrby'"
     ]
    }
   ],
   "source": [
    "conn.hincrby('test', 'count', 3)"
   ]
  },
  {
   "cell_type": "code",
   "execution_count": 30,
   "id": "811aaa00",
   "metadata": {},
   "outputs": [
    {
     "ename": "AttributeError",
     "evalue": "'Engine' object has no attribute 'hget'",
     "output_type": "error",
     "traceback": [
      "\u001b[1;31m---------------------------------------------------------------------------\u001b[0m",
      "\u001b[1;31mAttributeError\u001b[0m                            Traceback (most recent call last)",
      "Cell \u001b[1;32mIn[30], line 1\u001b[0m\n\u001b[1;32m----> 1\u001b[0m conn\u001b[38;5;241m.\u001b[39mhget(\u001b[38;5;124m'\u001b[39m\u001b[38;5;124mtest\u001b[39m\u001b[38;5;124m'\u001b[39m, \u001b[38;5;124m'\u001b[39m\u001b[38;5;124mcount\u001b[39m\u001b[38;5;124m'\u001b[39m)\n",
      "\u001b[1;31mAttributeError\u001b[0m: 'Engine' object has no attribute 'hget'"
     ]
    }
   ],
   "source": [
    "conn.hget('test', 'count')"
   ]
  },
  {
   "cell_type": "code",
   "execution_count": null,
   "id": "b6ff5d5f",
   "metadata": {},
   "outputs": [],
   "source": []
  },
  {
   "cell_type": "code",
   "execution_count": null,
   "id": "a32419ab",
   "metadata": {},
   "outputs": [],
   "source": []
  },
  {
   "cell_type": "code",
   "execution_count": null,
   "id": "f58546e8",
   "metadata": {},
   "outputs": [],
   "source": []
  },
  {
   "cell_type": "code",
   "execution_count": null,
   "id": "3d9a65c1",
   "metadata": {},
   "outputs": [],
   "source": []
  }
 ],
 "metadata": {
  "kernelspec": {
   "display_name": "Python 3 (ipykernel)",
   "language": "python",
   "name": "python3"
  },
  "language_info": {
   "codemirror_mode": {
    "name": "ipython",
    "version": 3
   },
   "file_extension": ".py",
   "mimetype": "text/x-python",
   "name": "python",
   "nbconvert_exporter": "python",
   "pygments_lexer": "ipython3",
   "version": "3.11.5"
  }
 },
 "nbformat": 4,
 "nbformat_minor": 5
}
